Workbook

Sheet Inputs
A1: Curvature measured from surveyors' triangles · workbook
A2: Blue = input you can change · black = formula · green = link to another sheet. Change the SNR cut or tier weights and the Result sheet recalculates.
A4: R0, fixed scale radius for SNR (m) | B4: 6371000 | C4: Fixed before the run; not a fit (RULE.md)
A5: Arc-seconds per radian | B5: 206264.81 | C5: 360·3600/(2π)
A6: SNR cut (keep triangles with SNR ≥ cut) | B6: 2 | C6: Declared rule: 2. Try 0, 1 or 3 (section 4 sensitivity)
A7: Tier A weight | B7: 1 | C7: Observed angles + 3 printed sides
A8: Tier B weight | B8: 0.5 | C8: Observed angles + 1–2 printed sides
A9: Tier C weight | B9: 0.25 | C9: Observed angles, coordinate area only

Sheet Result
A1: Main result · recalculates from the Triangles sheet and the Inputs
A2: Expected with the declared inputs: 391 triangles, q = 0.9953 ± 0.0048, K = 2.4501 × 10⁻¹⁴ m⁻², R = 6,389 km (scripts/rule_fit.py).
A4: Triangles in the result | B4: =SUM(Triangles!$K$2:$K$1006) -> 391
A5: Σ w·A·ε | B5: =SUMPRODUCT(Triangles!$P$2:$P$1006,Triangles!$D$2:$D$1006,Triangles!$E$2:$E$1006) -> 10198081
A6: Σ w·A² | B6: =SUMPRODUCT(Triangles!$P$2:$P$1006,Triangles!$D$2:$D$1006,Triangles!$D$2:$D$1006) -> 2.0179584e+09
A7: K measured (″ per km²) | B7: =B5/B6 -> 0.0050536624
A8: K ellipsoid, same weights (″ per km²) | B8: =SUMPRODUCT(Triangles!$P$2:$P$1006,Triangles!$D$2:$D$1006,Triangles!$F$2:$F$1006,Triangles!$D$2:$D$1006)/B6 -> 0.0050774761
A9: Ratio q = K / K ellipsoid | B9: =B7/B8 -> 0.99530994 | C9: Main result
A10: Variance of K (sandwich) | B10: =SUMPRODUCT(Triangles!$P$2:$P$1006,Triangles!$P$2:$P$1006,Triangles!$D$2:$D$1006,Triangles!$D$2:$D$1006,Triangles!$G$2:$G$1006,Triangles!$G$2:$G$1006)/B6^2 -> 4.9535531e-10
A11: χ²/dof | B11: =SUM(Triangles!$Q$2:$Q$1006)/(B4-1) -> 1.1966574
A12: σ of K (″ per km²), inflated if χ²/dof > 1 | B12: =SQRT(B10)*MAX(1,SQRT(B11)) -> 2.434688e-05
A13: σ of q | B13: =B12/B8 -> 0.0047950754 | C13: Main result
A14: z (q vs 1) | B14: =(B9-1)/B13 -> -0.97809905
A15: K measured (m⁻², ×10⁻¹⁴) | B15: =B7/Inputs!$B$5/1000000*100000000000000 -> 2.4500847 | C15: Main result
A16: σ of K (m⁻², ×10⁻¹⁴) | B16: =B12/Inputs!$B$5/1000000*100000000000000 -> 0.011803701
A17: Radius 1/√K (km) | B17: =1/SQRT(B15*0.00000000000001)/1000 -> 6388.6553 | C17: Main result
A20: By survey (unweighted within a survey, as in section 4)
A21: Survey | B21: Triangles | C21: K (″/km²) | D21: K ellipsoid (″/km²) | E21: q | F21: σ of q
A22: US 39th parallel | B22: =SUMPRODUCT((Triangles!$A$2:$A$1006=A22)*Triangles!$K$2:$K$1006) -> 118 | C22: =SUMPRODUCT((Triangles!$A$2:$A$1006=A22)*Triangles!$K$2:$K$1006,Triangles!$D$2:$D$1006,Triangles!$E$2:$E$1006)/SUMPRODUCT((Triangles!$A$2:$A$1006=A22)*Triangles!$K$2:$K$1006,Triangles!$D$2:$D$1006,Triangles!$D$2:$D$1006) -> 0.0050754286 | D22: =SUMPRODUCT((Triangles!$A$2:$A$1006=A22)*Triangles!$K$2:$K$1006,Triangles!$D$2:$D$1006,Triangles!$F$2:$F$1006,Triangles!$D$2:$D$1006)/SUMPRODUCT((Triangles!$A$2:$A$1006=A22)*Triangles!$K$2:$K$1006,Triangles!$D$2:$D$1006,Triangles!$D$2:$D$1006) -> 0.0050777107 | E22: =C22/D22 -> 0.99955058 | F22: =INDEX(Triangles!$G$2:$G$1006,MATCH(A22,Triangles!$A$2:$A$1006,0))/SQRT(SUMPRODUCT((Triangles!$A$2:$A$1006=A22)*Triangles!$K$2:$K$1006,Triangles!$D$2:$D$1006,Triangles!$D$2:$D$1006))/D22 -> 0.004782387
A23: US Eastern Oblique | B23: =SUMPRODUCT((Triangles!$A$2:$A$1006=A23)*Triangles!$K$2:$K$1006) -> 157 | C23: =SUMPRODUCT((Triangles!$A$2:$A$1006=A23)*Triangles!$K$2:$K$1006,Triangles!$D$2:$D$1006,Triangles!$E$2:$E$1006)/SUMPRODUCT((Triangles!$A$2:$A$1006=A23)*Triangles!$K$2:$K$1006,Triangles!$D$2:$D$1006,Triangles!$D$2:$D$1006) -> 0.0049241928 | D23: =SUMPRODUCT((Triangles!$A$2:$A$1006=A23)*Triangles!$K$2:$K$1006,Triangles!$D$2:$D$1006,Triangles!$F$2:$F$1006,Triangles!$D$2:$D$1006)/SUMPRODUCT((Triangles!$A$2:$A$1006=A23)*Triangles!$K$2:$K$1006,Triangles!$D$2:$D$1006,Triangles!$D$2:$D$1006) -> 0.0050767732 | E23: =C23/D23 -> 0.9699454 | F23: =INDEX(Triangles!$G$2:$G$1006,MATCH(A23,Triangles!$A$2:$A$1006,0))/SQRT(SUMPRODUCT((Triangles!$A$2:$A$1006=A23)*Triangles!$K$2:$K$1006,Triangles!$D$2:$D$1006,Triangles!$D$2:$D$1006))/D23 -> 0.014294784
A24: Maclear, Cape 1837–48 | B24: =SUMPRODUCT((Triangles!$A$2:$A$1006=A24)*Triangles!$K$2:$K$1006) -> 52 | C24: =SUMPRODUCT((Triangles!$A$2:$A$1006=A24)*Triangles!$K$2:$K$1006,Triangles!$D$2:$D$1006,Triangles!$E$2:$E$1006)/SUMPRODUCT((Triangles!$A$2:$A$1006=A24)*Triangles!$K$2:$K$1006,Triangles!$D$2:$D$1006,Triangles!$D$2:$D$1006) -> 0.0050968989 | D24: =SUMPRODUCT((Triangles!$A$2:$A$1006=A24)*Triangles!$K$2:$K$1006,Triangles!$D$2:$D$1006,Triangles!$F$2:$F$1006,Triangles!$D$2:$D$1006)/SUMPRODUCT((Triangles!$A$2:$A$1006=A24)*Triangles!$K$2:$K$1006,Triangles!$D$2:$D$1006,Triangles!$D$2:$D$1006) -> 0.0050856006 | E24: =C24/D24 -> 1.0022216 | F24: =INDEX(Triangles!$G$2:$G$1006,MATCH(A24,Triangles!$A$2:$A$1006,0))/SQRT(SUMPRODUCT((Triangles!$A$2:$A$1006=A24)*Triangles!$K$2:$K$1006,Triangles!$D$2:$D$1006,Triangles!$D$2:$D$1006))/D24 -> 0.024651135
A25: Europe 52°N (Helmert) | B25: =SUMPRODUCT((Triangles!$A$2:$A$1006=A25)*Triangles!$K$2:$K$1006) -> 45 | C25: =SUMPRODUCT((Triangles!$A$2:$A$1006=A25)*Triangles!$K$2:$K$1006,Triangles!$D$2:$D$1006,Triangles!$E$2:$E$1006)/SUMPRODUCT((Triangles!$A$2:$A$1006=A25)*Triangles!$K$2:$K$1006,Triangles!$D$2:$D$1006,Triangles!$D$2:$D$1006) -> 0.0048496198 | D25: =SUMPRODUCT((Triangles!$A$2:$A$1006=A25)*Triangles!$K$2:$K$1006,Triangles!$D$2:$D$1006,Triangles!$F$2:$F$1006,Triangles!$D$2:$D$1006)/SUMPRODUCT((Triangles!$A$2:$A$1006=A25)*Triangles!$K$2:$K$1006,Triangles!$D$2:$D$1006,Triangles!$D$2:$D$1006) -> 0.0050634322 | E25: =C25/D25 -> 0.95777323 | F25: =INDEX(Triangles!$G$2:$G$1006,MATCH(A25,Triangles!$A$2:$A$1006,0))/SQRT(SUMPRODUCT((Triangles!$A$2:$A$1006=A25)*Triangles!$K$2:$K$1006,Triangles!$D$2:$D$1006,Triangles!$D$2:$D$1006))/D25 -> 0.025030405
A26: Transvaal–Rhodesia | B26: =SUMPRODUCT((Triangles!$A$2:$A$1006=A26)*Triangles!$K$2:$K$1006) -> 9 | C26: =SUMPRODUCT((Triangles!$A$2:$A$1006=A26)*Triangles!$K$2:$K$1006,Triangles!$D$2:$D$1006,Triangles!$E$2:$E$1006)/SUMPRODUCT((Triangles!$A$2:$A$1006=A26)*Triangles!$K$2:$K$1006,Triangles!$D$2:$D$1006,Triangles!$D$2:$D$1006) -> 0.0040755785 | D26: =SUMPRODUCT((Triangles!$A$2:$A$1006=A26)*Triangles!$K$2:$K$1006,Triangles!$D$2:$D$1006,Triangles!$F$2:$F$1006,Triangles!$D$2:$D$1006)/SUMPRODUCT((Triangles!$A$2:$A$1006=A26)*Triangles!$K$2:$K$1006,Triangles!$D$2:$D$1006,Triangles!$D$2:$D$1006) -> 0.0050955226 | E26: =C26/D26 -> 0.79983523 | F26: =INDEX(Triangles!$G$2:$G$1006,MATCH(A26,Triangles!$A$2:$A$1006,0))/SQRT(SUMPRODUCT((Triangles!$A$2:$A$1006=A26)*Triangles!$K$2:$K$1006,Triangles!$D$2:$D$1006,Triangles!$D$2:$D$1006))/D26 -> 0.11069396
A27: India GTS meridional | B27: =SUMPRODUCT((Triangles!$A$2:$A$1006=A27)*Triangles!$K$2:$K$1006) -> 4 | C27: =SUMPRODUCT((Triangles!$A$2:$A$1006=A27)*Triangles!$K$2:$K$1006,Triangles!$D$2:$D$1006,Triangles!$E$2:$E$1006)/SUMPRODUCT((Triangles!$A$2:$A$1006=A27)*Triangles!$K$2:$K$1006,Triangles!$D$2:$D$1006,Triangles!$D$2:$D$1006) -> 0.0063201719 | D27: =SUMPRODUCT((Triangles!$A$2:$A$1006=A27)*Triangles!$K$2:$K$1006,Triangles!$D$2:$D$1006,Triangles!$F$2:$F$1006,Triangles!$D$2:$D$1006)/SUMPRODUCT((Triangles!$A$2:$A$1006=A27)*Triangles!$K$2:$K$1006,Triangles!$D$2:$D$1006,Triangles!$D$2:$D$1006) -> 0.0051013234 | E27: =C27/D27 -> 1.2389279 | F27: =INDEX(Triangles!$G$2:$G$1006,MATCH(A27,Triangles!$A$2:$A$1006,0))/SQRT(SUMPRODUCT((Triangles!$A$2:$A$1006=A27)*Triangles!$K$2:$K$1006,Triangles!$D$2:$D$1006,Triangles!$D$2:$D$1006))/D27 -> 0.12762825
A28: England OS 1787–96 | B28: =SUMPRODUCT((Triangles!$A$2:$A$1006=A28)*Triangles!$K$2:$K$1006) -> 6 | C28: =SUMPRODUCT((Triangles!$A$2:$A$1006=A28)*Triangles!$K$2:$K$1006,Triangles!$D$2:$D$1006,Triangles!$E$2:$E$1006)/SUMPRODUCT((Triangles!$A$2:$A$1006=A28)*Triangles!$K$2:$K$1006,Triangles!$D$2:$D$1006,Triangles!$D$2:$D$1006) -> 0.0037714326 | D28: =SUMPRODUCT((Triangles!$A$2:$A$1006=A28)*Triangles!$K$2:$K$1006,Triangles!$D$2:$D$1006,Triangles!$F$2:$F$1006,Triangles!$D$2:$D$1006)/SUMPRODUCT((Triangles!$A$2:$A$1006=A28)*Triangles!$K$2:$K$1006,Triangles!$D$2:$D$1006,Triangles!$D$2:$D$1006) -> 0.0050635819 | E28: =C28/D28 -> 0.74481517 | F28: =INDEX(Triangles!$G$2:$G$1006,MATCH(A28,Triangles!$A$2:$A$1006,0))/SQRT(SUMPRODUCT((Triangles!$A$2:$A$1006=A28)*Triangles!$K$2:$K$1006,Triangles!$D$2:$D$1006,Triangles!$D$2:$D$1006))/D28 -> 0.1142657
A30: σ of q per survey here is before χ² inflation; section 4 of the report applies it.

Sheet Triangles
A1: Survey | B1: Triangle | C1: Tier | D1: Area used (km²) | E1: Observed excess Σangles−180° (″) | F1: K ellipsoid 1/(MN) (″ per km²) | G1: Survey closure σ (″) | H1: Expected excess A·K (″) | I1: SNR | J1: Tier weight | K1: In result | L1: In chain sum | M1: Area from coordinates (km²) | N1: Printed excess (″) | O1: QC note | P1: Fit weight w = tier/σ² (if in result) | Q1: Residual² (if in result)
A2: Anglo-French 1787 | B2: Hanger Hill Tower - Hampton Poor-house - King's Arbour | C2: A | D2: 45.3723 | E2: -1 | F2: 0.0050627703 | G2: 1.3442 | H2: =D2*F2 -> 0.22970953 | I2: =IF(G2="","",D2*1000000/Inputs!$B$4^2*Inputs!$B$5/G2) -> 0.17152871 | J2: =IF(C2="A",Inputs!$B$7,IF(C2="B",Inputs!$B$8,IF(C2="C",Inputs!$B$9,0))) -> 1 | K2: =IF(AND(E2<>"",G2<>"",J2>0),IF(I2>=Inputs!$B$6,1,0),0) -> 0 | L2: 0 | M2: 45.2204 | N2: 0.29 | O2: ok | P2: =IF(K2=1,J2/G2^2,0) -> 0 | Q2: =IF(K2=1,((E2-Result!$B$7*D2)/G2)^2,0) -> 0
A3: Anglo-French 1787 | B3: St. Ann's Hill - Hampton Poor-house - King's Arbour | C3: B | D3: 42.2137 | E3: -0.4 | F3: 0.0050628188 | G3: 1.3442 | H3: =D3*F3 -> 0.21372032 | I3: =IF(G3="","",D3*1000000/Inputs!$B$4^2*Inputs!$B$5/G3) -> 0.15958771 | J3: =IF(C3="A",Inputs!$B$7,IF(C3="B",Inputs!$B$8,IF(C3="C",Inputs!$B$9,0))) -> 0.5 | K3: =IF(AND(E3<>"",G3<>"",J3>0),IF(I3>=Inputs!$B$6,1,0),0) -> 0 | L3: 0 | M3: 42.0201 | N3: 0.21 | O3: ok | P3: =IF(K3=1,J3/G3^2,0) -> 0 | Q3: =IF(K3=1,((E3-Result!$B$7*D3)/G3)^2,0) -> 0
A4: Anglo-French 1787 | B4: Windsor Castle, Wardrobe Tower - King's Arbour - St. Ann's Hill | D4: 49.2762 | F4: 0.0050627969 | G4: 1.3442 | H4: =D4*F4 -> 0.24947539 | I4: =IF(G4="","",D4*1000000/Inputs!$B$4^2*Inputs!$B$5/G4) -> 0.1862873 | J4: =IF(C4="A",Inputs!$B$7,IF(C4="B",Inputs!$B$8,IF(C4="C",Inputs!$B$9,0))) -> 0 | K4: =IF(AND(E4<>"",G4<>"",J4>0),IF(I4>=Inputs!$B$6,1,0),0) -> 0 | L4: 0 | M4: 49.2762 | N4: 0.25 | O4: ok | P4: =IF(K4=1,J4/G4^2,0) -> 0 | Q4: =IF(K4=1,((E4-Result!$B$7*D4)/G4)^2,0) -> 0
A5: Anglo-French 1787 | B5: Hundred Acres - Hanger Hill Tower - St. Ann's Hill | C5: B | D5: 214.0675 | E5: -0.75 | F5: 0.0050628361 | G5: 1.3442 | H5: =D5*F5 -> 1.0837887 | I5: =IF(G5="","",D5*1000000/Inputs!$B$4^2*Inputs!$B$5/G5) -> 0.8092762 | J5: =IF(C5="A",Inputs!$B$7,IF(C5="B",Inputs!$B$8,IF(C5="C",Inputs!$B$9,0))) -> 0.5 | K5: =IF(AND(E5<>"",G5<>"",J5>0),IF(I5>=Inputs!$B$6,1,0),0) -> 0 | L5: 0 | M5: 213.2789 | N5: 1.08 | O5: ok | P5: =IF(K5=1,J5/G5^2,0) -> 0 | Q5: =IF(K5=1,((E5-Result!$B$7*D5)/G5)^2,0) -> 0
A6: Anglo-French 1787 | B6: Severndroog Castle - Hanger Hill Tower - Hundred Acres | C6: B | D6: 233.4519 | E6: 1.05 | F6: 0.0050628095 | G6: 1.3442 | H6: =D6*F6 -> 1.1819225 | I6: =IF(G6="","",D6*1000000/Inputs!$B$4^2*Inputs!$B$5/G6) -> 0.88255838 | J6: =IF(C6="A",Inputs!$B$7,IF(C6="B",Inputs!$B$8,IF(C6="C",Inputs!$B$9,0))) -> 0.5 | K6: =IF(AND(E6<>"",G6<>"",J6>0),IF(I6>=Inputs!$B$6,1,0),0) -> 0 | L6: 0 | M6: 232.5278 | N6: 1.18 | O6: ok | P6: =IF(K6=1,J6/G6^2,0) -> 0 | Q6: =IF(K6=1,((E6-Result!$B$7*D6)/G6)^2,0) -> 0
A7: Anglo-French 1787 | B7: Norwood - Hanger Hill Tower - Severndroog Castle | C7: B | D7: 110.2082 | E7: 1 | F7: 0.0050627816 | G7: 1.3442 | H7: =D7*F7 -> 0.55796004 | I7: =IF(G7="","",D7*1000000/Inputs!$B$4^2*Inputs!$B$5/G7) -> 0.41663902 | J7: =IF(C7="A",Inputs!$B$7,IF(C7="B",Inputs!$B$8,IF(C7="C",Inputs!$B$9,0))) -> 0.5 | K7: =IF(AND(E7<>"",G7<>"",J7>0),IF(I7>=Inputs!$B$6,1,0),0) -> 0 | L7: 0 | M7: 109.7378 | N7: 0.44 | O7: ok | P7: =IF(K7=1,J7/G7^2,0) -> 0 | Q7: =IF(K7=1,((E7-Result!$B$7*D7)/G7)^2,0) -> 0
A8: Anglo-French 1787 | B8: Norwood - Hanger Hill Tower - Hundred Acres | D8: 105.1201 | F8: 0.0050628312 | G8: 1.3442 | H8: =D8*F8 -> 0.53220532 | I8: =IF(G8="","",D8*1000000/Inputs!$B$4^2*Inputs!$B$5/G8) -> 0.3974036 | J8: =IF(C8="A",Inputs!$B$7,IF(C8="B",Inputs!$B$8,IF(C8="C",Inputs!$B$9,0))) -> 0 | K8: =IF(AND(E8<>"",G8<>"",J8>0),IF(I8>=Inputs!$B$6,1,0),0) -> 0 | L8: 0 | M8: 105.1201 | N8: 0.53 | O8: ok | P8: =IF(K8=1,J8/G8^2,0) -> 0 | Q8: =IF(K8=1,((E8-Result!$B$7*D8)/G8)^2,0) -> 0
A9: Anglo-French 1787 | B9: Greenwich Observatory, Transit Room - Severndroog Castle - Norwood | C9: B | D9: 19.6872 | E9: 2 | F9: 0.0050627992 | G9: 1.3442 | H9: =D9*F9 -> 0.09967234 | I9: =IF(G9="","",D9*1000000/Inputs!$B$4^2*Inputs!$B$5/G9) -> 0.074426909 | J9: =IF(C9="A",Inputs!$B$7,IF(C9="B",Inputs!$B$8,IF(C9="C",Inputs!$B$9,0))) -> 0.5 | K9: =IF(AND(E9<>"",G9<>"",J9>0),IF(I9>=Inputs!$B$6,1,0),0) -> 0 | L9: 0 | M9: 19.5889 | N9: 0.01 | O9: ok | P9: =IF(K9=1,J9/G9^2,0) -> 0 | Q9: =IF(K9=1,((E9-Result!$B$7*D9)/G9)^2,0) -> 0
A10: Anglo-French 1787 | B10: Botley Hill - Hundred Acres - Severndroog Castle | C10: B | D10: 153.1923 | E10: -0.05 | F10: 0.0050629041 | G10: 1.3442 | H10: =D10*F10 -> 0.77559793 | I10: =IF(G10="","",D10*1000000/Inputs!$B$4^2*Inputs!$B$5/G10) -> 0.57913921 | J10: =IF(C10="A",Inputs!$B$7,IF(C10="B",Inputs!$B$8,IF(C10="C",Inputs!$B$9,0))) -> 0.5 | K10: =IF(AND(E10<>"",G10<>"",J10>0),IF(I10>=Inputs!$B$6,1,0),0) -> 0 | L10: 0 | M10: 152.475 | N10: 0.78 | O10: ok | P10: =IF(K10=1,J10/G10^2,0) -> 0 | Q10: =IF(K10=1,((E10-Result!$B$7*D10)/G10)^2,0) -> 0
A11: Anglo-French 1787 | B11: Wrotham Hill - Botley Hill - Severndroog Castle | C11: B | D11: 220.3761 | E11: 1 | F11: 0.0050629131 | G11: 1.3442 | H11: =D11*F11 -> 1.115745 | I11: =IF(G11="","",D11*1000000/Inputs!$B$4^2*Inputs!$B$5/G11) -> 0.83312569 | J11: =IF(C11="A",Inputs!$B$7,IF(C11="B",Inputs!$B$8,IF(C11="C",Inputs!$B$9,0))) -> 0.5 | K11: =IF(AND(E11<>"",G11<>"",J11>0),IF(I11>=Inputs!$B$6,1,0),0) -> 0 | L11: 0 | M11: 224.658 | N11: 1.12 | O11: ok | P11: =IF(K11=1,J11/G11^2,0) -> 0 | Q11: =IF(K11=1,((E11-Result!$B$7*D11)/G11)^2,0) -> 0
A12: Anglo-French 1787 | B12: Frant - Botley Hill - Wrotham Hill | C12: B | D12: 257.5567 | E12: 1.45 | F12: 0.0050630554 | G12: 1.3442 | H12: =D12*F12 -> 1.3040238 | I12: =IF(G12="","",D12*1000000/Inputs!$B$4^2*Inputs!$B$5/G12) -> 0.97368591 | J12: =IF(C12="A",Inputs!$B$7,IF(C12="B",Inputs!$B$8,IF(C12="C",Inputs!$B$9,0))) -> 0.5 | K12: =IF(AND(E12<>"",G12<>"",J12>0),IF(I12>=Inputs!$B$6,1,0),0) -> 0 | L12: 0 | M12: 261.4555 | N12: 1.3 | O12: ok | P12: =IF(K12=1,J12/G12^2,0) -> 0 | Q12: =IF(K12=1,((E12-Result!$B$7*D12)/G12)^2,0) -> 0
A13: Anglo-French 1787 | B13: Hollingborn Hill - Wrotham Hill - Frant | D13: 293.0477 | F13: 0.0050630606 | G13: 1.3442 | H13: =D13*F13 -> 1.4837183 | I13: =IF(G13="","",D13*1000000/Inputs!$B$4^2*Inputs!$B$5/G13) -> 1.1078586 | J13: =IF(C13="A",Inputs!$B$7,IF(C13="B",Inputs!$B$8,IF(C13="C",Inputs!$B$9,0))) -> 0 | K13: =IF(AND(E13<>"",G13<>"",J13>0),IF(I13>=Inputs!$B$6,1,0),0) -> 0 | L13: 0 | M13: 293.0477 | N13: 1.52 | O13: ok | P13: =IF(K13=1,J13/G13^2,0) -> 0 | Q13: =IF(K13=1,((E13-Result!$B$7*D13)/G13)^2,0) -> 0
A14: Anglo-French 1787 | B14: Fairlight Down - Frant - Hollingborn Hill | D14: 558.6645 | F14: 0.0050632298 | G14: 1.3442 | H14: =D14*F14 -> 2.8286468 | I14: =IF(G14="","",D14*1000000/Inputs!$B$4^2*Inputs!$B$5/G14) -> 2.1120155 | J14: =IF(C14="A",Inputs!$B$7,IF(C14="B",Inputs!$B$8,IF(C14="C",Inputs!$B$9,0))) -> 0 | K14: =IF(AND(E14<>"",G14<>"",J14>0),IF(I14>=Inputs!$B$6,1,0),0) -> 0 | L14: 0 | M14: 558.6645 | N14: 2.85 | O14: ok | P14: =IF(K14=1,J14/G14^2,0) -> 0 | Q14: =IF(K14=1,((E14-Result!$B$7*D14)/G14)^2,0) -> 0
A15: Anglo-French 1787 | B15: Goudhurst - Botley Hill - Wrotham Hill | C15: B | D15: 265.7618 | E15: -1.5 | F15: 0.0050630494 | G15: 1.3442 | H15: =D15*F15 -> 1.3455651 | I15: =IF(G15="","",D15*1000000/Inputs!$B$4^2*Inputs!$B$5/G15) -> 1.0047051 | J15: =IF(C15="A",Inputs!$B$7,IF(C15="B",Inputs!$B$8,IF(C15="C",Inputs!$B$9,0))) -> 0.5 | K15: =IF(AND(E15<>"",G15<>"",J15>0),IF(I15>=Inputs!$B$6,1,0),0) -> 0 | L15: 0 | M15: 269.1793 | N15: 1.35 | O15: ok | P15: =IF(K15=1,J15/G15^2,0) -> 0 | Q15: =IF(K15=1,((E15-Result!$B$7*D15)/G15)^2,0) -> 0
A16: Anglo-French 1787 | B16: Goudhurst - Frant - Wrotham Hill | C16: B | D16: 159.1896 | E16: 1.3 | F16: 0.005063119 | G16: 1.3442 | H16: =D16*F16 -> 0.80599589 | I16: =IF(G16="","",D16*1000000/Inputs!$B$4^2*Inputs!$B$5/G16) -> 0.60181183 | J16: =IF(C16="A",Inputs!$B$7,IF(C16="B",Inputs!$B$8,IF(C16="C",Inputs!$B$9,0))) -> 0.5 | K16: =IF(AND(E16<>"",G16<>"",J16>0),IF(I16>=Inputs!$B$6,1,0),0) -> 0 | L16: 0 | M16: 158.0181 | N16: 0.81 | O16: ok | P16: =IF(K16=1,J16/G16^2,0) -> 0 | Q16: =IF(K16=1,((E16-Result!$B$7*D16)/G16)^2,0) -> 0
A17: Anglo-French 1787 | B17: Hollingborn Hill - Wrotham Hill - Goudhurst | C17: C | D17: 235.8218 | E17: -1 | F17: 0.0050630546 | G17: 1.3442 | H17: =D17*F17 -> 1.1939786 | I17: =IF(G17="","",D17*1000000/Inputs!$B$4^2*Inputs!$B$5/G17) -> 0.89151772 | J17: =IF(C17="A",Inputs!$B$7,IF(C17="B",Inputs!$B$8,IF(C17="C",Inputs!$B$9,0))) -> 0.25 | K17: =IF(AND(E17<>"",G17<>"",J17>0),IF(I17>=Inputs!$B$6,1,0),0) -> 0 | L17: 0 | M17: 235.8218 | N17: 1.22 | O17: ok | P17: =IF(K17=1,J17/G17^2,0) -> 0 | Q17: =IF(K17=1,((E17-Result!$B$7*D17)/G17)^2,0) -> 0
A18: Anglo-French 1787 | B18: Tenterden - Goudhurst - Hollingborn Hill | D18: 166.4426 | F18: 0.0050631498 | G18: 1.3442 | H18: =D18*F18 -> 0.84272381 | I18: =IF(G18="","",D18*1000000/Inputs!$B$4^2*Inputs!$B$5/G18) -> 0.6292316 | J18: =IF(C18="A",Inputs!$B$7,IF(C18="B",Inputs!$B$8,IF(C18="C",Inputs!$B$9,0))) -> 0 | K18: =IF(AND(E18<>"",G18<>"",J18>0),IF(I18>=Inputs!$B$6,1,0),0) -> 0 | L18: 0 | M18: 166.4426 | N18: 0.85 | O18: ok | P18: =IF(K18=1,J18/G18^2,0) -> 0 | Q18: =IF(K18=1,((E18-Result!$B$7*D18)/G18)^2,0) -> 0
A19: Anglo-French 1787 | B19: Fairlight Down - Goudhurst - Tenterden | D19: 179.4396 | F19: 0.0050632997 | G19: 1.3442 | H19: =D19*F19 -> 0.90855648 | I19: =IF(G19="","",D19*1000000/Inputs!$B$4^2*Inputs!$B$5/G19) -> 0.67836639 | J19: =IF(C19="A",Inputs!$B$7,IF(C19="B",Inputs!$B$8,IF(C19="C",Inputs!$B$9,0))) -> 0 | K19: =IF(AND(E19<>"",G19<>"",J19>0),IF(I19>=Inputs!$B$6,1,0),0) -> 0 | L19: 0 | M19: 179.4396 | N19: 0.91 | O19: ok | P19: =IF(K19=1,J19/G19^2,0) -> 0 | Q19: =IF(K19=1,((E19-Result!$B$7*D19)/G19)^2,0) -> 0
A20: Anglo-French 1787 | B20: Allington Knoll - Hollingborn Hill - Tenterden | D20: 205.1427 | F20: 0.005063163 | G20: 1.3442 | H20: =D20*F20 -> 1.0386709 | I20: =IF(G20="","",D20*1000000/Inputs!$B$4^2*Inputs!$B$5/G20) -> 0.77553624 | J20: =IF(C20="A",Inputs!$B$7,IF(C20="B",Inputs!$B$8,IF(C20="C",Inputs!$B$9,0))) -> 0 | K20: =IF(AND(E20<>"",G20<>"",J20>0),IF(I20>=Inputs!$B$6,1,0),0) -> 0 | L20: 0 | M20: 205.1427 | N20: 1.05 | O20: ok | P20: =IF(K20=1,J20/G20^2,0) -> 0 | Q20: =IF(K20=1,((E20-Result!$B$7*D20)/G20)^2,0) -> 0
A21: Anglo-French 1787 | B21: Lydd - Allington Knoll - Tenterden | D21: 130.7041 | F21: 0.0050632841 | G21: 1.3442 | H21: =D21*F21 -> 0.66179199 | I21: =IF(G21="","",D21*1000000/Inputs!$B$4^2*Inputs!$B$5/G21) -> 0.4941232 | J21: =IF(C21="A",Inputs!$B$7,IF(C21="B",Inputs!$B$8,IF(C21="C",Inputs!$B$9,0))) -> 0 | K21: =IF(AND(E21<>"",G21<>"",J21>0),IF(I21>=Inputs!$B$6,1,0),0) -> 0 | L21: 0 | M21: 130.7041 | N21: 0.67 | O21: ok | P21: =IF(K21=1,J21/G21^2,0) -> 0 | Q21: =IF(K21=1,((E21-Result!$B$7*D21)/G21)^2,0) -> 0
A22: Anglo-French 1787 | B22: Fairlight Down - Lydd - Tenterden | D22: 194.4977 | F22: 0.0050633624 | G22: 1.3442 | H22: =D22*F22 -> 0.98481233 | I22: =IF(G22="","",D22*1000000/Inputs!$B$4^2*Inputs!$B$5/G22) -> 0.73529312 | J22: =IF(C22="A",Inputs!$B$7,IF(C22="B",Inputs!$B$8,IF(C22="C",Inputs!$B$9,0))) -> 0 | K22: =IF(AND(E22<>"",G22<>"",J22>0),IF(I22>=Inputs!$B$6,1,0),0) -> 0 | L22: 0 | M22: 194.4977 | N22: 0.99 | O22: ok | P22: =IF(K22=1,J22/G22^2,0) -> 0 | Q22: =IF(K22=1,((E22-Result!$B$7*D22)/G22)^2,0) -> 0
A23: Anglo-French 1787 | B23: Allington Knoll - Lydd - Fairlight Down | D23: 128.7996 | F23: 0.0050633583 | G23: 1.3442 | H23: =D23*F23 -> 0.65215852 | I23: =IF(G23="","",D23*1000000/Inputs!$B$4^2*Inputs!$B$5/G23) -> 0.48692329 | J23: =IF(C23="A",Inputs!$B$7,IF(C23="B",Inputs!$B$8,IF(C23="C",Inputs!$B$9,0))) -> 0 | K23: =IF(AND(E23<>"",G23<>"",J23>0),IF(I23>=Inputs!$B$6,1,0),0) -> 0 | L23: 0 | M23: 128.7996 | N23: 0.33 | O23: ok | P23: =IF(K23=1,J23/G23^2,0) -> 0 | Q23: =IF(K23=1,((E23-Result!$B$7*D23)/G23)^2,0) -> 0
A24: Anglo-French 1787 | B24: Lydd - Ruckinge - High Nook | C24: A | D24: 41.5336 | E24: -0.25 | F24: 0.0050633086 | G24: 1.3442 | H24: =D24*F24 -> 0.21029743 | I24: =IF(G24="","",D24*1000000/Inputs!$B$4^2*Inputs!$B$5/G24) -> 0.15701661 | J24: =IF(C24="A",Inputs!$B$7,IF(C24="B",Inputs!$B$8,IF(C24="C",Inputs!$B$9,0))) -> 1 | K24: =IF(AND(E24<>"",G24<>"",J24>0),IF(I24>=Inputs!$B$6,1,0),0) -> 0 | L24: 0 | M24: 41.3368 | N24: 0.21 | O24: ok | P24: =IF(K24=1,J24/G24^2,0) -> 0 | Q24: =IF(K24=1,((E24-Result!$B$7*D24)/G24)^2,0) -> 0
A25: Anglo-French 1787 | B25: Allington Knoll - Ruckinge - High Nook | C25: B | D25: 17.2825 | E25: -2 | F25: 0.0050632593 | G25: 1.3442 | H25: =D25*F25 -> 0.087505778 | I25: =IF(G25="","",D25*1000000/Inputs!$B$4^2*Inputs!$B$5/G25) -> 0.065336008 | J25: =IF(C25="A",Inputs!$B$7,IF(C25="B",Inputs!$B$8,IF(C25="C",Inputs!$B$9,0))) -> 0.5 | K25: =IF(AND(E25<>"",G25<>"",J25>0),IF(I25>=Inputs!$B$6,1,0),0) -> 0 | L25: 0 | M25: 17.2017 | N25: 0.09 | O25: ok | P25: =IF(K25=1,J25/G25^2,0) -> 0 | Q25: =IF(K25=1,((E25-Result!$B$7*D25)/G25)^2,0) -> 0
A26: Anglo-French 1787 | B26: Folkstone Turnpike - Allington Knoll - High Nook | C26: B | D26: 57.9645 | E26: 1 | F26: 0.0050632474 | G26: 1.3442 | H26: =D26*F26 -> 0.2934886 | I26: =IF(G26="","",D26*1000000/Inputs!$B$4^2*Inputs!$B$5/G26) -> 0.21913317 | J26: =IF(C26="A",Inputs!$B$7,IF(C26="B",Inputs!$B$8,IF(C26="C",Inputs!$B$9,0))) -> 0.5 | K26: =IF(AND(E26<>"",G26<>"",J26>0),IF(I26>=Inputs!$B$6,1,0),0) -> 0 | L26: 0 | M26: 57.6923 | N26: 0.29 | O26: ok | P26: =IF(K26=1,J26/G26^2,0) -> 0 | Q26: =IF(K26=1,((E26-Result!$B$7*D26)/G26)^2,0) -> 0
A27: Anglo-French 1787 | B27: Folkstone Turnpike - Allington Knoll - Lydd | D27: 115.4315 | F27: 0.0050632737 | G27: 1.3442 | H27: =D27*F27 -> 0.58446127 | I27: =IF(G27="","",D27*1000000/Inputs!$B$4^2*Inputs!$B$5/G27) -> 0.43638556 | J27: =IF(C27="A",Inputs!$B$7,IF(C27="B",Inputs!$B$8,IF(C27="C",Inputs!$B$9,0))) -> 0 | K27: =IF(AND(E27<>"",G27<>"",J27>0),IF(I27>=Inputs!$B$6,1,0),0) -> 0 | L27: 0 | M27: 115.4315 | N27: 0.59 | O27: ok | P27: =IF(K27=1,J27/G27^2,0) -> 0 | Q27: =IF(K27=1,((E27-Result!$B$7*D27)/G27)^2,0) -> 0
A28: Anglo-French 1787 | B28: Padlesworth - High Nook - Folkstone Turnpike | D28: 30.8382 | F28: 0.005063234 | G28: 1.3442 | H28: =D28*F28 -> 0.15614102 | I28: =IF(G28="","",D28*1000000/Inputs!$B$4^2*Inputs!$B$5/G28) -> 0.11658295 | J28: =IF(C28="A",Inputs!$B$7,IF(C28="B",Inputs!$B$8,IF(C28="C",Inputs!$B$9,0))) -> 0 | K28: =IF(AND(E28<>"",G28<>"",J28>0),IF(I28>=Inputs!$B$6,1,0),0) -> 0 | L28: 0 | M28: 30.8382 | N28: 0.16 | O28: ok | P28: =IF(K28=1,J28/G28^2,0) -> 0 | Q28: =IF(K28=1,((E28-Result!$B$7*D28)/G28)^2,0) -> 0
A29: Anglo-French 1787 | B29: Padlesworth - Lydd - Folkstone Turnpike | D29: 51.4034 | F29: 0.0050632603 | G29: 1.3442 | H29: =D29*F29 -> 0.26026879 | I29: =IF(G29="","",D29*1000000/Inputs!$B$4^2*Inputs!$B$5/G29) -> 0.19432912 | J29: =IF(C29="A",Inputs!$B$7,IF(C29="B",Inputs!$B$8,IF(C29="C",Inputs!$B$9,0))) -> 0 | K29: =IF(AND(E29<>"",G29<>"",J29>0),IF(I29>=Inputs!$B$6,1,0),0) -> 0 | L29: 0 | M29: 51.4034 | N29: 0.27 | O29: ok | P29: =IF(K29=1,J29/G29^2,0) -> 0 | Q29: =IF(K29=1,((E29-Result!$B$7*D29)/G29)^2,0) -> 0
A30: Anglo-French 1787 | B30: Padlesworth - Lydd - Fairlight Down | D30: 114.7453 | F30: 0.0050633449 | G30: 1.3442 | H30: =D30*F30 -> 0.58099503 | I30: =IF(G30="","",D30*1000000/Inputs!$B$4^2*Inputs!$B$5/G30) -> 0.4337914 | J30: =IF(C30="A",Inputs!$B$7,IF(C30="B",Inputs!$B$8,IF(C30="C",Inputs!$B$9,0))) -> 0 | K30: =IF(AND(E30<>"",G30<>"",J30>0),IF(I30>=Inputs!$B$6,1,0),0) -> 0 | L30: 0 | M30: 114.7453 | N30: 0.59 | O30: ok | P30: =IF(K30=1,J30/G30^2,0) -> 0 | Q30: =IF(K30=1,((E30-Result!$B$7*D30)/G30)^2,0) -> 0
A31: Anglo-French 1787 | B31: Swingfield - Padlesworth - Folkstone Turnpike | C31: C | D31: 10.6993 | E31: 0 | F31: 0.005063185 | G31: 1.3442 | H31: =D31*F31 -> 0.054172535 | I31: =IF(G31="","",D31*1000000/Inputs!$B$4^2*Inputs!$B$5/G31) -> 0.040448405 | J31: =IF(C31="A",Inputs!$B$7,IF(C31="B",Inputs!$B$8,IF(C31="C",Inputs!$B$9,0))) -> 0.25 | K31: =IF(AND(E31<>"",G31<>"",J31>0),IF(I31>=Inputs!$B$6,1,0),0) -> 0 | L31: 0 | M31: 10.6993 | N31: 0.06 | O31: ok | P31: =IF(K31=1,J31/G31^2,0) -> 0 | Q31: =IF(K31=1,((E31-Result!$B$7*D31)/G31)^2,0) -> 0
A32: Anglo-French 1787 | B32: Dover Castle - Swingfield - Folkstone Turnpike | C32: B | D32: 25.4721 | E32: 0 | F32: 0.0050631788 | G32: 1.3442 | H32: =D32*F32 -> 0.1289698 | I32: =IF(G32="","",D32*1000000/Inputs!$B$4^2*Inputs!$B$5/G32) -> 0.096296562 | J32: =IF(C32="A",Inputs!$B$7,IF(C32="B",Inputs!$B$8,IF(C32="C",Inputs!$B$9,0))) -> 0.5 | K32: =IF(AND(E32<>"",G32<>"",J32>0),IF(I32>=Inputs!$B$6,1,0),0) -> 0 | L32: 0 | M32: 25.3696 | N32: 0.13 | O32: ok | P32: =IF(K32=1,J32/G32^2,0) -> 0 | Q32: =IF(K32=1,((E32-Result!$B$7*D32)/G32)^2,0) -> 0
A33: Anglo-French 1787 | B33: Dover Castle - Padlesworth - Fairlight Down | D33: 133.7011 | F33: 0.005063276 | G33: 1.3442 | H33: =D33*F33 -> 0.67696557 | I33: =IF(G33="","",D33*1000000/Inputs!$B$4^2*Inputs!$B$5/G33) -> 0.50545327 | J33: =IF(C33="A",Inputs!$B$7,IF(C33="B",Inputs!$B$8,IF(C33="C",Inputs!$B$9,0))) -> 0 | K33: =IF(AND(E33<>"",G33<>"",J33>0),IF(I33>=Inputs!$B$6,1,0),0) -> 0 | L33: 0 | M33: 133.7011 | N33: 0.69 | O33: ok | P33: =IF(K33=1,J33/G33^2,0) -> 0 | Q33: =IF(K33=1,((E33-Result!$B$7*D33)/G33)^2,0) -> 0
A34: Anglo-French 1787 | B34: Dover Castle - Fairlight Down - Montlambert | D34: 1451.3323 | F34: 0.0050634297 | G34: 1.3442 | H34: =D34*F34 -> 7.3487191 | I34: =IF(G34="","",D34*1000000/Inputs!$B$4^2*Inputs!$B$5/G34) -> 5.4867212 | J34: =IF(C34="A",Inputs!$B$7,IF(C34="B",Inputs!$B$8,IF(C34="C",Inputs!$B$9,0))) -> 0 | K34: =IF(AND(E34<>"",G34<>"",J34>0),IF(I34>=Inputs!$B$6,1,0),0) -> 0 | L34: 0 | M34: 1451.3323 | N34: 7.4 | O34: ok | P34: =IF(K34=1,J34/G34^2,0) -> 0 | Q34: =IF(K34=1,((E34-Result!$B$7*D34)/G34)^2,0) -> 0
A35: Anglo-French 1787 | B35: Fairlight Down - Dover Castle - Blancnez | D35: 937.8161 | F35: 0.0050633491 | G35: 1.3442 | H35: =D35*F35 -> 4.7484903 | I35: =IF(G35="","",D35*1000000/Inputs!$B$4^2*Inputs!$B$5/G35) -> 3.5453876 | J35: =IF(C35="A",Inputs!$B$7,IF(C35="B",Inputs!$B$8,IF(C35="C",Inputs!$B$9,0))) -> 0 | K35: =IF(AND(E35<>"",G35<>"",J35>0),IF(I35>=Inputs!$B$6,1,0),0) -> 0 | L35: 0 | M35: 937.8161 | N35: 4.78 | O35: ok | P35: =IF(K35=1,J35/G35^2,0) -> 0 | Q35: =IF(K35=1,((E35-Result!$B$7*D35)/G35)^2,0) -> 0
A36: Anglo-French 1787 | B36: Dover Castle - Montlambert - Blancnez | D36: 361.7423 | F36: 0.0050634111 | G36: 1.3442 | H36: =D36*F36 -> 1.83165 | I36: =IF(G36="","",D36*1000000/Inputs!$B$4^2*Inputs!$B$5/G36) -> 1.3675567 | J36: =IF(C36="A",Inputs!$B$7,IF(C36="B",Inputs!$B$8,IF(C36="C",Inputs!$B$9,0))) -> 0 | K36: =IF(AND(E36<>"",G36<>"",J36>0),IF(I36>=Inputs!$B$6,1,0),0) -> 0 | L36: 0 | M36: 361.7423 | N36: 1.84 | O36: ok | P36: =IF(K36=1,J36/G36^2,0) -> 0 | Q36: =IF(K36=1,((E36-Result!$B$7*D36)/G36)^2,0) -> 0
A37: Anglo-French 1787 | B37: N.D. at Calais - Blancnez - Dover Castle | D37: 163.999 | F37: 0.0050633177 | G37: 1.3442 | H37: =D37*F37 -> 0.83037904 | I37: =IF(G37="","",D37*1000000/Inputs!$B$4^2*Inputs!$B$5/G37) -> 0.61999364 | J37: =IF(C37="A",Inputs!$B$7,IF(C37="B",Inputs!$B$8,IF(C37="C",Inputs!$B$9,0))) -> 0 | K37: =IF(AND(E37<>"",G37<>"",J37>0),IF(I37>=Inputs!$B$6,1,0),0) -> 0 | L37: 0 | M37: 163.999 | N37: 0.84 | O37: ok | P37: =IF(K37=1,J37/G37^2,0) -> 0 | Q37: =IF(K37=1,((E37-Result!$B$7*D37)/G37)^2,0) -> 0
A38: Anglo-French 1787 | B38: N.D. at Calais - Dover Castle - Point M near Dunkirk | D38: 473.9782 | F38: 0.0050632771 | G38: 1.3442 | H38: =D38*F38 -> 2.399883 | I38: =IF(G38="","",D38*1000000/Inputs!$B$4^2*Inputs!$B$5/G38) -> 1.7918613 | J38: =IF(C38="A",Inputs!$B$7,IF(C38="B",Inputs!$B$8,IF(C38="C",Inputs!$B$9,0))) -> 0 | K38: =IF(AND(E38<>"",G38<>"",J38>0),IF(I38>=Inputs!$B$6,1,0),0) -> 0 | L38: 0 | M38: 473.9782 | N38: 2.42 | O38: ok | P38: =IF(K38=1,J38/G38^2,0) -> 0 | Q38: =IF(K38=1,((E38-Result!$B$7*D38)/G38)^2,0) -> 0
A39: Anglo-French 1787 | B39: Blancnez - N.D. at Calais - Dover Castle | C39: A | D39: 164.7439 | E39: 0.8 | F39: 0.0050633177 | G39: 1.3442 | H39: =D39*F39 -> 0.8341507 | I39: =IF(G39="","",D39*1000000/Inputs!$B$4^2*Inputs!$B$5/G39) -> 0.62280971 | J39: =IF(C39="A",Inputs!$B$7,IF(C39="B",Inputs!$B$8,IF(C39="C",Inputs!$B$9,0))) -> 1 | K39: =IF(AND(E39<>"",G39<>"",J39>0),IF(I39>=Inputs!$B$6,1,0),0) -> 0 | L39: 0 | M39: 163.999 | O39: ok | P39: =IF(K39=1,J39/G39^2,0) -> 0 | Q39: =IF(K39=1,((E39-Result!$B$7*D39)/G39)^2,0) -> 0
A40: Anglo-French 1787 | B40: Blancnez - Dover Castle - Montlambert | C40: A | D40: 363.5427 | E40: 1.8 | F40: 0.0050634111 | G40: 1.3442 | H40: =D40*F40 -> 1.8407662 | I40: =IF(G40="","",D40*1000000/Inputs!$B$4^2*Inputs!$B$5/G40) -> 1.374363 | J40: =IF(C40="A",Inputs!$B$7,IF(C40="B",Inputs!$B$8,IF(C40="C",Inputs!$B$9,0))) -> 1 | K40: =IF(AND(E40<>"",G40<>"",J40>0),IF(I40>=Inputs!$B$6,1,0),0) -> 0 | L40: 0 | M40: 361.7423 | O40: ok | P40: =IF(K40=1,J40/G40^2,0) -> 0 | Q40: =IF(K40=1,((E40-Result!$B$7*D40)/G40)^2,0) -> 0
...

Sheet Chain_sums
A1: Whole-chain sums over non-overlapping triangles (Appendix B)
A3: Chain | B3: Triangles | C3: Area (km²) | D3: Σ excess observed (″) | E3: Σ expected (″) | F3: Noise σ√n (″) | G3: K/K ellipsoid | H3: Shortfall per triangle (″)
A4: US 39th parallel | B4: =SUMPRODUCT((Triangles!$A$2:$A$1006=A4)*Triangles!$L$2:$L$1006) -> 241 | C4: =SUMPRODUCT((Triangles!$A$2:$A$1006=A4)*Triangles!$L$2:$L$1006,Triangles!$D$2:$D$1006) -> 322644.47 | D4: =SUMPRODUCT((Triangles!$A$2:$A$1006=A4)*Triangles!$L$2:$L$1006,Triangles!$E$2:$E$1006) -> 1604.335 | E4: =SUMPRODUCT((Triangles!$A$2:$A$1006=A4)*Triangles!$L$2:$L$1006,Triangles!$H$2:$H$1006) -> 1638.3072 | F4: =INDEX(Triangles!$G$2:$G$1006,MATCH(A4,Triangles!$A$2:$A$1006,0))*SQRT(B4) -> 19.580642 | G4: =D4/E4 -> 0.97926384 | H4: =(D4-E4)/B4 -> -0.14096347
A5: US Eastern Oblique | B5: =SUMPRODUCT((Triangles!$A$2:$A$1006=A5)*Triangles!$L$2:$L$1006) -> 114 | C5: =SUMPRODUCT((Triangles!$A$2:$A$1006=A5)*Triangles!$L$2:$L$1006,Triangles!$D$2:$D$1006) -> 112582.34 | D5: =SUMPRODUCT((Triangles!$A$2:$A$1006=A5)*Triangles!$L$2:$L$1006,Triangles!$E$2:$E$1006) -> 539.525 | E5: =SUMPRODUCT((Triangles!$A$2:$A$1006=A5)*Triangles!$L$2:$L$1006,Triangles!$H$2:$H$1006) -> 571.75178 | F5: =INDEX(Triangles!$G$2:$G$1006,MATCH(A5,Triangles!$A$2:$A$1006,0))*SQRT(B5) -> 14.918014 | G5: =D5/E5 -> 0.94363502 | H5: =(D5-E5)/B5 -> -0.28269106
A6: Maclear, Cape 1837–48 | B6: =SUMPRODUCT((Triangles!$A$2:$A$1006=A6)*Triangles!$L$2:$L$1006) -> 18 | C6: =SUMPRODUCT((Triangles!$A$2:$A$1006=A6)*Triangles!$L$2:$L$1006,Triangles!$D$2:$D$1006) -> 43539.602 | D6: =SUMPRODUCT((Triangles!$A$2:$A$1006=A6)*Triangles!$L$2:$L$1006,Triangles!$E$2:$E$1006) -> 230.5 | E6: =SUMPRODUCT((Triangles!$A$2:$A$1006=A6)*Triangles!$L$2:$L$1006,Triangles!$H$2:$H$1006) -> 221.4292 | F6: =INDEX(Triangles!$G$2:$G$1006,MATCH(A6,Triangles!$A$2:$A$1006,0))*SQRT(B6) -> 7.6452385 | G6: =D6/E6 -> 1.0409648 | H6: =(D6-E6)/B6 -> 0.50393332
A7: Core three combined | B7: =SUM(B4:B6) -> 373 | C7: =SUM(C4:C6) -> 478766.41 | D7: =SUM(D4:D6) -> 2374.36 | E7: =SUM(E4:E6) -> 2431.4882 | F7: =SQRT(SUMPRODUCT(F4:F6,F4:F6)) -> 25.775925 | G7: =D7/E7 -> 0.97650485 | H7: =(D7-E7)/B7 -> -0.15315865

Sheet Source_check
A1: KML entries checked against the printed tables (Schott 1900, 1902)
A3: Pages read entry by entry
A4: Report | B4: Printed page | C4: PDF page | D4: Triangles on page | E4: Angles | F4: All match KML
A5: Schott 1900 | B5: 414 | C5: 424 | D5: 9 | E5: =D5*3 -> 27 | F5: Yes
A6: Schott 1900 | B6: 474 | C6: 485 | D6: 9 | E6: =D6*3 -> 27 | F6: Yes
A7: Schott 1900 | B7: 588 | C7: 616 | D7: 9 | E7: =D7*3 -> 27 | F7: Yes
A8: Schott 1900 | B8: 591 | C8: 619 | D8: 9 | E8: =D8*3 -> 27 | F8: Yes
A9: Schott 1902 | B9: 131 | C9: 153 | D9: 12 | E9: =D9*3 -> 36 | F9: Yes
A10: Total | D10: =SUM(D5:D9) -> 48 | E10: =SUM(E5:E9) -> 144
A12: Three printed misprints, corrected from the printed sides by the law of cosines
A13: Triangle | B13: Source | C13: Station with misprint | D13: Printed angle (°) | E13: Side opposite it (m) | F13: Other side b (m) | G13: Other side c (m) | H13: Angle from sides (°) | I13: Corrected angle (°)
A14: Mount Nebo – Wheeler Peak – Ibepah | B14: Schott 1900 p. 591 no. 33 | C14: Ibepah | D14: 10 09 30.489 | E14: 237769.08 | F14: 99493.31 | G14: 184375.27 | H14: =DEGREES(ACOS((F14^2+G14^2-E14^2)/(2*F14*G14))) -> 110.15442 | I14: 110 09 30.489
A15: Cherry Ridge – Twin Creek – Round Top | B15: Schott 1900 p. 414 no. 25 | C15: Cherry Ridge | D15: 20 10 13.41 | E15: 11997.12 | F15: 24389.25 | G15: 18130.38 | H15: =DEGREES(ACOS((F15^2+G15^2-E15^2)/(2*F15*G15))) -> 28.17057 | I15: 28 10 13.41
A16: Gunstock – Mount Pleasant – Mount Independence | B16: Schott 1902 p. 131 no. 16 | C16: Mount Pleasant | D16: 19 54 04.38 | E16: 88811.79 | F16: 50110.16 | G16: 71681.66 | H16: =DEGREES(ACOS((F16^2+G16^2-E16^2)/(2*F16*G16))) -> 91.90048 | I16: 91 54 04.38
A18: Sides are the printed "Distances in metres" for each triangle. The angle from sides matches the corrected degrees to within the rounding of the printed sides.
